{"uid":"632eb34e3bf36a26","name":"test_delete_user_authorized_as_another_user","fullName":"tests.test_user_delete.TestUserDelete#test_delete_user_authorized_as_another_user","historyId":"f921dd3d5d139c34912ef23ea50982dc","time":{"start":1697127757868,"stop":1697127761637,"duration":3769},"description":"This test verifies that one user cannot delete another user","descriptionHtml":"<p>This test verifies that one user cannot delete another user</p>\n","status":"skipped","statusMessage":"XFAIL This test is expected to fail due to a known defect\n\nAssertionError: Unexpected status code 200\nassert 200 == 400\n +  where 200 = <Response [200]>.status_code","statusTrace":"self = <tests.test_user_delete.TestUserDelete object at 0x7fc6623e4050>\n\n    @pytest.mark.xfail(reason=\"This test is expected to fail due to a known defect\")\n    @allure.description(\"This test verifies that one user cannot delete another user\")\n    def test_delete_user_authorized_as_another_user(self):\n        # Создание двух пользователей\n        first_user_data = self.preapare_registration_data()\n        response_first_user = MyRequests.post(\"/user/\", data=first_user_data)\n        first_user_id = self.get_json_value(response_first_user, \"id\")\n        second_user_data = self.preapare_registration_data()\n        MyRequests.post(\"/user/\", data=second_user_data)\n    \n        # Авторизация под вторым пользователем\n        response1 = MyRequests.post(\"/user/login\",\n                                    data={'email': second_user_data['email'], 'password': second_user_data['password']})\n        auth_sid = self.get_cookie(response1, \"auth_sid\")\n        token = self.get_header(response1, \"x-csrf-token\")\n    \n        # Попытка удалить первого пользователя из-под учетной записи второго пользователя\n        response2 = MyRequests.delete(f\"/user/{first_user_id}\",\n                                      headers={\"x-csrf-token\": token},\n                                      cookies={\"auth_sid\": auth_sid})\n>       assert response2.status_code == 400, f\"Unexpected status code {response2.status_code}\"\nE       AssertionError: Unexpected status code 200\nE       assert 200 == 400\nE        +  where 200 = <Response [200]>.status_code\n\ntests/test_user_delete.py:71: AssertionError","flaky":false,"newFailed":false,"newBroken":false,"newPassed":false,"retriesCount":0,"retriesStatusChange":false,"beforeStages":[],"testStage":{"description":"This test verifies that one user cannot delete another user","status":"skipped","statusMessage":"XFAIL This test is expected to fail due to a known defect\n\nAssertionError: Unexpected status code 200\nassert 200 == 400\n +  where 200 = <Response [200]>.status_code","statusTrace":"self = <tests.test_user_delete.TestUserDelete object at 0x7fc6623e4050>\n\n    @pytest.mark.xfail(reason=\"This test is expected to fail due to a known defect\")\n    @allure.description(\"This test verifies that one user cannot delete another user\")\n    def test_delete_user_authorized_as_another_user(self):\n        # Создание двух пользователей\n        first_user_data = self.preapare_registration_data()\n        response_first_user = MyRequests.post(\"/user/\", data=first_user_data)\n        first_user_id = self.get_json_value(response_first_user, \"id\")\n        second_user_data = self.preapare_registration_data()\n        MyRequests.post(\"/user/\", data=second_user_data)\n    \n        # Авторизация под вторым пользователем\n        response1 = MyRequests.post(\"/user/login\",\n                                    data={'email': second_user_data['email'], 'password': second_user_data['password']})\n        auth_sid = self.get_cookie(response1, \"auth_sid\")\n        token = self.get_header(response1, \"x-csrf-token\")\n    \n        # Попытка удалить первого пользователя из-под учетной записи второго пользователя\n        response2 = MyRequests.delete(f\"/user/{first_user_id}\",\n                                      headers={\"x-csrf-token\": token},\n                                      cookies={\"auth_sid\": auth_sid})\n>       assert response2.status_code == 400, f\"Unexpected status code {response2.status_code}\"\nE       AssertionError: Unexpected status code 200\nE       assert 200 == 400\nE        +  where 200 = <Response [200]>.status_code\n\ntests/test_user_delete.py:71: AssertionError","steps":[{"name":"POST request to URL '/user/'","time":{"start":1697127757869,"stop":1697127759084,"duration":1215},"status":"passed","steps":[],"attachments":[],"parameters":[],"shouldDisplayMessage":false,"stepsCount":0,"attachmentsCount":0,"hasContent":false},{"name":"POST request to URL '/user/'","time":{"start":1697127759084,"stop":1697127760052,"duration":968},"status":"passed","steps":[],"attachments":[],"parameters":[],"shouldDisplayMessage":false,"stepsCount":0,"attachmentsCount":0,"hasContent":false},{"name":"POST request to URL '/user/login'","time":{"start":1697127760053,"stop":1697127760509,"duration":456},"status":"passed","steps":[],"attachments":[],"parameters":[],"shouldDisplayMessage":false,"stepsCount":0,"attachmentsCount":0,"hasContent":false},{"name":"DELETE request to URL '/user/82215'","time":{"start":1697127760509,"stop":1697127761637,"duration":1128},"status":"passed","steps":[],"attachments":[],"parameters":[],"shouldDisplayMessage":false,"stepsCount":0,"attachmentsCount":0,"hasContent":false}],"attachments":[],"parameters":[],"shouldDisplayMessage":true,"stepsCount":4,"attachmentsCount":0,"hasContent":true},"afterStages":[],"labels":[{"name":"epic","value":"User Deletion Tests"},{"name":"tag","value":"@pytest.mark.xfail(reason='This test is expected to fail due to a known defect')"},{"name":"parentSuite","value":"tests"},{"name":"suite","value":"test_user_delete"},{"name":"subSuite","value":"TestUserDelete"},{"name":"host","value":"fv-az934-584"},{"name":"thread","value":"2203-MainThread"},{"name":"framework","value":"pytest"},{"name":"language","value":"cpython3"},{"name":"package","value":"tests.test_user_delete"},{"name":"resultFormat","value":"allure2"}],"parameters":[],"links":[],"hidden":false,"retry":false,"extra":{"severity":"normal","retries":[],"categories":[],"history":{"statistic":{"failed":0,"broken":0,"skipped":5,"passed":0,"unknown":0,"total":5},"items":[{"uid":"288c88e7ae3b0013","reportUrl":"https://Badx86.github.io/LearnQA_Python_API/2//#testresult/288c88e7ae3b0013","status":"skipped","statusDetails":"XFAIL This test is expected to fail due to a known defect\n\nAssertionError: Unexpected status code 200\nassert 200 == 400\n +  where 200 = <Response [200]>.status_code","time":{"start":1697126826606,"stop":1697126830544,"duration":3938}},{"uid":"a84e76e0c41f76c8","reportUrl":"https://Badx86.github.io/LearnQA_Python_API/1//#testresult/a84e76e0c41f76c8","status":"skipped","statusDetails":"XFAIL This test is expected to fail due to a known defect\n\nAssertionError: Unexpected status code 200\nassert 200 == 400\n +  where 200 = <Response [200]>.status_code","time":{"start":1697126394496,"stop":1697126399019,"duration":4523}},{"uid":"2abe45f833481de7","reportUrl":"https://Badx86.github.io/LearnQA_Python_API/2//#testresult/2abe45f833481de7","status":"skipped","statusDetails":"XFAIL This test is expected to fail due to a known defect\n\nAssertionError: Unexpected status code 200\nassert 200 == 400\n +  where 200 = <Response [200]>.status_code","time":{"start":1697126044363,"stop":1697126049130,"duration":4767}},{"uid":"8a08365e643f0eb0","reportUrl":"https://Badx86.github.io/LearnQA_Python_API/1//#testresult/8a08365e643f0eb0","status":"skipped","statusDetails":"XFAIL This test is expected to fail due to a known defect\n\nAssertionError: Unexpected status code 200\nassert 200 == 400\n +  where 200 = <Response [200]>.status_code","time":{"start":1697125835000,"stop":1697125839742,"duration":4742}}]},"tags":["@pytest.mark.xfail(reason='This test is expected to fail due to a known defect')"]},"source":"632eb34e3bf36a26.json","parameterValues":[]}