{"uid":"d0ac7509e9de016b","name":"test_delete_user_authorized_as_another_user","fullName":"tests.test_user_delete.TestUserDelete#test_delete_user_authorized_as_another_user","historyId":"f921dd3d5d139c34912ef23ea50982dc","time":{"start":1697123970345,"stop":1697123973600,"duration":3255},"description":"This test verifies that one user cannot delete another user","descriptionHtml":"<p>This test verifies that one user cannot delete another user</p>\n","status":"skipped","statusMessage":"XFAIL This test is expected to fail due to a known defect\n\nAssertionError: Unexpected status code 200\nassert 200 == 400\n +  where 200 = <Response [200]>.status_code","statusTrace":"self = <tests.test_user_delete.TestUserDelete object at 0x0000018C5C797E50>\n\n    @pytest.mark.xfail(reason=\"This test is expected to fail due to a known defect\")\n    @allure.description(\"This test verifies that one user cannot delete another user\")\n    def test_delete_user_authorized_as_another_user(self):\n        # Создание двух пользователей\n        first_user_data = self.preapare_registration_data()\n        response_first_user = MyRequests.post(\"/user/\", data=first_user_data)\n        first_user_id = self.get_json_value(response_first_user, \"id\")\n        second_user_data = self.preapare_registration_data()\n        MyRequests.post(\"/user/\", data=second_user_data)\n    \n        # Авторизация под вторым пользователем\n        response1 = MyRequests.post(\"/user/login\",\n                                    data={'email': second_user_data['email'], 'password': second_user_data['password']})\n        auth_sid = self.get_cookie(response1, \"auth_sid\")\n        token = self.get_header(response1, \"x-csrf-token\")\n    \n        # Попытка удалить первого пользователя из-под учетной записи второго пользователя\n        response2 = MyRequests.delete(f\"/user/{first_user_id}\",\n                                      headers={\"x-csrf-token\": token},\n                                      cookies={\"auth_sid\": auth_sid})\n>       assert response2.status_code == 400, f\"Unexpected status code {response2.status_code}\"\nE       AssertionError: Unexpected status code 200\nE       assert 200 == 400\nE        +  where 200 = <Response [200]>.status_code\n\ntests\\test_user_delete.py:71: AssertionError","flaky":false,"newFailed":false,"newBroken":false,"newPassed":false,"retriesCount":0,"retriesStatusChange":false,"beforeStages":[],"testStage":{"description":"This test verifies that one user cannot delete another user","status":"skipped","statusMessage":"XFAIL This test is expected to fail due to a known defect\n\nAssertionError: Unexpected status code 200\nassert 200 == 400\n +  where 200 = <Response [200]>.status_code","statusTrace":"self = <tests.test_user_delete.TestUserDelete object at 0x0000018C5C797E50>\n\n    @pytest.mark.xfail(reason=\"This test is expected to fail due to a known defect\")\n    @allure.description(\"This test verifies that one user cannot delete another user\")\n    def test_delete_user_authorized_as_another_user(self):\n        # Создание двух пользователей\n        first_user_data = self.preapare_registration_data()\n        response_first_user = MyRequests.post(\"/user/\", data=first_user_data)\n        first_user_id = self.get_json_value(response_first_user, \"id\")\n        second_user_data = self.preapare_registration_data()\n        MyRequests.post(\"/user/\", data=second_user_data)\n    \n        # Авторизация под вторым пользователем\n        response1 = MyRequests.post(\"/user/login\",\n                                    data={'email': second_user_data['email'], 'password': second_user_data['password']})\n        auth_sid = self.get_cookie(response1, \"auth_sid\")\n        token = self.get_header(response1, \"x-csrf-token\")\n    \n        # Попытка удалить первого пользователя из-под учетной записи второго пользователя\n        response2 = MyRequests.delete(f\"/user/{first_user_id}\",\n                                      headers={\"x-csrf-token\": token},\n                                      cookies={\"auth_sid\": auth_sid})\n>       assert response2.status_code == 400, f\"Unexpected status code {response2.status_code}\"\nE       AssertionError: Unexpected status code 200\nE       assert 200 == 400\nE        +  where 200 = <Response [200]>.status_code\n\ntests\\test_user_delete.py:71: AssertionError","steps":[{"name":"POST request to URL '/user/'","time":{"start":1697123970345,"stop":1697123971271,"duration":926},"status":"passed","steps":[],"attachments":[],"parameters":[],"shouldDisplayMessage":false,"stepsCount":0,"attachmentsCount":0,"hasContent":false},{"name":"POST request to URL '/user/'","time":{"start":1697123971271,"stop":1697123972197,"duration":926},"status":"passed","steps":[],"attachments":[],"parameters":[],"shouldDisplayMessage":false,"stepsCount":0,"attachmentsCount":0,"hasContent":false},{"name":"POST request to URL '/user/login'","time":{"start":1697123972199,"stop":1697123972617,"duration":418},"status":"passed","steps":[],"attachments":[],"parameters":[],"shouldDisplayMessage":false,"stepsCount":0,"attachmentsCount":0,"hasContent":false},{"name":"DELETE request to URL '/user/82135'","time":{"start":1697123972617,"stop":1697123973600,"duration":983},"status":"passed","steps":[],"attachments":[],"parameters":[],"shouldDisplayMessage":false,"stepsCount":0,"attachmentsCount":0,"hasContent":false}],"attachments":[],"parameters":[],"shouldDisplayMessage":true,"stepsCount":4,"attachmentsCount":0,"hasContent":true},"afterStages":[],"labels":[{"name":"epic","value":"User Delete Functionality"},{"name":"tag","value":"@pytest.mark.xfail(reason='This test is expected to fail due to a known defect')"},{"name":"parentSuite","value":"tests"},{"name":"suite","value":"test_user_delete"},{"name":"subSuite","value":"TestUserDelete"},{"name":"host","value":"LAPTOP-SFQ2DO00"},{"name":"thread","value":"5760-MainThread"},{"name":"framework","value":"pytest"},{"name":"language","value":"cpython3"},{"name":"package","value":"tests.test_user_delete"},{"name":"resultFormat","value":"allure2"}],"parameters":[],"links":[],"hidden":true,"retry":true,"extra":{"categories":[],"tags":["@pytest.mark.xfail(reason='This test is expected to fail due to a known defect')"]},"source":"d0ac7509e9de016b.json","parameterValues":[]}